<?xml version="1.0"?>
<robot xmlns:xacro="http://ros.org/wiki/xacro">
  <xacro:macro name="wheel" params="side parent x y z">
    <link name="wheel_${side}">
      <visual>
        <origin xyz="0 0 0.025" rpy="0 1.57 1.57"/>
        <geometry>
          <cylinder length="0.05" radius="0.10"/>
        </geometry>
        <material name="Gray"/>
      </visual>
      <collision>
        <origin xyz="0 0 0.025" rpy="0 1.57 1.57"/>
        <geometry>
          <cylinder length="0.05" radius="0.10"/>
        </geometry>
      </collision>
      <inertial>
        <mass value="1.0"/>
        <origin xyz="0 0 0.025"/>
        <inertia ixx="0.01" ixy="0" ixz="0" iyy="0.01" iyz="0" izz="0.01"/>
      </inertial>
    </link>
    <joint name="wheel_${side}_joint" type="continuous">
      <parent link="${parent}"/>
      <child link="wheel_${side}"/>
      <origin xyz="${x} ${y} ${z}" rpy="0 0 0"/>
      <axis xyz="0 0 1"/>
    </joint>

    <transmission type="transmission_interface/SimpleTransmission" name="wheel_${side}_trans">
      <actuator name="wheel_${side}_motor">
        <hardwareInterface>hardware_interface/VelocityJointInterface</hardwareInterface>
      </actuator>
      <joint name="wheel_${side}_joint">
        <hardwareInterface>hardware_interface/VelocityJointInterface</hardwareInterface>
      </joint>
    </transmission>
  </xacro:macro>
</robot>
