<?xml version="1.0"?>
<robot xmlns:xacro="http://ros.org/wiki/xacro">
  <xacro:macro name="manipulator" params="parent_link base_height">

    <link name="link1">
      <visual>
        <origin xyz="0 0 0.025" rpy="0 0 0"/>
        <geometry>
          <box size="0.050 0.050 0.100"/>
        </geometry>
        <material name="Red"/>
      </visual>
      <collision>
        <origin xyz="0 0 0.025" rpy="0 0 0"/>
        <geometry>
          <box size="0.050 0.050 0.100"/>
        </geometry>
      </collision>
      <inertial>
        <mass value="1.0"/>
        <origin xyz="0 0 0.025"/>
        <inertia ixx="0.001" ixy="0" ixz="0" iyy="0.001" iyz="0" izz="0.001"/>
      </inertial>
    </link>
    <joint name="joint1" type="revolute">
      <parent link="${parent_link}"/>
      <child link="link1"/>
      <origin xyz="0 0 0.100" rpy="0 0 0"/>
      <axis xyz="0 1 1"/>
      <limit lower="-1.57" upper="1.57" effort="10" velocity="1"/>
    </joint>

    <link name="link2">
      <visual>
        <origin xyz="0 0 0.025" rpy="0 0 0"/>
        <geometry>
          <box size="0.050 0.050 0.100"/>
        </geometry>
        <material name="Green"/>
      </visual>
      <collision>
        <origin xyz="0 0 0.025" rpy="0 0 0"/>
        <geometry>
          <box size="0.050 0.050 0.100"/>
        </geometry>
      </collision>
      <inertial>
        <mass value="0.8"/>
        <origin xyz="0 0 0.025"/>
        <inertia ixx="0.0008" ixy="0" ixz="0" iyy="0.0008" iyz="0" izz="0.0008"/>
      </inertial>
    </link>
    <joint name="joint2" type="revolute">
      <parent link="link1"/>
      <child link="link2"/>
      <origin xyz="0 0 0.100" rpy="0 0 0"/>
      <axis xyz="0 1 0"/>
      <limit lower="-1.57" upper="1.57" effort="10" velocity="1"/>
    </joint>


    <link name="link3">
      <visual>
        <origin xyz="0 0 0.025" rpy="0 0 0"/>
        <geometry>
          <box size="0.050 0.050 0.100"/>
        </geometry>
        <material name="Yellow"/>
      </visual>
      <collision>
        <origin xyz="0 0 0.025" rpy="0 0 0"/>
        <geometry>
          <box size="0.050 0.050 0.100"/>
        </geometry>
      </collision>
      <inertial>
        <mass value="0.6"/>
        <origin xyz="0 0 0.025"/>
        <inertia ixx="0.0006" ixy="0" ixz="0" iyy="0.0006" iyz="0" izz="0.0006"/>
      </inertial>
    </link>
    <joint name="joint3" type="revolute">
      <parent link="link2"/>
      <child link="link3"/>
      <origin xyz="0 0 0.100" rpy="0 0 0"/>
      <axis xyz="1 0 0"/>
      <limit lower="-1.57" upper="1.57" effort="10" velocity="1"/>
    </joint>


    <link name="link4">
      <visual>
        <origin xyz="0 0 0.025" rpy="0 0 0"/>
        <geometry>
          <box size="0.050 0.050 0.100"/>
        </geometry>
        <material name="Orange"/>
      </visual>
      <collision>
        <origin xyz="0 0 0.025" rpy="0 0 0"/>
        <geometry>
          <box size="0.050 0.050 0.100"/>
        </geometry>
      </collision>
      <inertial>
        <mass value="0.5"/>
        <origin xyz="0 0 0.025"/>
        <inertia ixx="0.0005" ixy="0" ixz="0" iyy="0.0005" iyz="0" izz="0.0005"/>
      </inertial>
    </link>
    <joint name="joint4" type="revolute">
      <parent link="link3"/>
      <child link="link4"/>
      <origin xyz="0 0 0.100" rpy="0 0 0"/>
      <axis xyz="0 1 0"/>
      <limit lower="-1.57" upper="1.57" effort="10" velocity="1"/>
    </joint>


    <link name="link5">
      <visual>
        <origin xyz="0 0 0.025" rpy="0 0 0"/>
        <geometry>
          <box size="0.050 0.050 0.100"/>
        </geometry>
        <material name="Purple"/>
      </visual>
      <collision>
        <origin xyz="0 0 0.025" rpy="0 0 0"/>
        <geometry>
          <box size="0.050 0.050 0.100"/>
        </geometry>
      </collision>
      <inertial>
        <mass value="0.4"/>
        <origin xyz="0 0 0.025"/>
        <inertia ixx="0.0004" ixy="0" ixz="0" iyy="0.0004" iyz="0" izz="0.0004"/>
      </inertial>
    </link>
    <joint name="joint5" type="continuous">
      <parent link="link4"/>
      <child link="link5"/>
      <origin xyz="0 0 0.100" rpy="0 0 0"/>
      <axis xyz="0 0 1"/>
    </joint>
  </xacro:macro>
</robot>
